[17:59:09] ‚úÖ Connected to database sqlite:////home/thalles/Documentos/ProjetosGit/Estudo_DeepSeek_Ollma/API/db/api_logs.db
[17:59:15] ‚úÖ Servidor iniciado com sucesso na porta 5000
[17:59:15] ‚úÖ Running on http://0.0.0.0:5000 (CTRL + C to quit)
[18:00:53] ‚úÖ Disconnected from database sqlite:////home/thalles/Documentos/ProjetosGit/Estudo_DeepSeek_Ollma/API/db/api_logs.db
[18:00:55] ‚úÖ Connected to database sqlite:////home/thalles/Documentos/ProjetosGit/Estudo_DeepSeek_Ollma/API/db/api_logs.db
[18:01:11] ‚úÖ Servidor iniciado com sucesso na porta 5000
[18:01:11] ‚úÖ Running on http://0.0.0.0:5000 (CTRL + C to quit)
[18:07:40] ‚õî Erro inesperado: 404 Not Found: The requested URL was not found on the server. If you entered the URL manually please check your spelling and try again.
[18:07:41] ‚õî Erro inesperado: 404 Not Found: The requested URL was not found on the server. If you entered the URL manually please check your spelling and try again.
[18:07:44] ‚õî Erro inesperado: 404 Not Found: The requested URL was not found on the server. If you entered the URL manually please check your spelling and try again.
[18:07:44] ‚õî Erro inesperado: 404 Not Found: The requested URL was not found on the server. If you entered the URL manually please check your spelling and try again.
[18:09:25] ‚úÖ Disconnected from database sqlite:////home/thalles/Documentos/ProjetosGit/Estudo_DeepSeek_Ollma/API/db/api_logs.db
[18:09:26] ‚úÖ Connected to database sqlite:////home/thalles/Documentos/ProjetosGit/Estudo_DeepSeek_Ollma/API/db/api_logs.db
[18:09:38] ‚úÖ Servidor iniciado com sucesso na porta 5000
[18:09:38] ‚úÖ Running on http://0.0.0.0:5000 (CTRL + C to quit)
[18:09:59] ‚õî Erro inesperado: 404 Not Found: The requested URL was not found on the server. If you entered the URL manually please check your spelling and try again.
[18:09:59] ‚õî Erro inesperado: 404 Not Found: The requested URL was not found on the server. If you entered the URL manually please check your spelling and try again.
[18:09:59] ‚õî Task exception was never retrieved
future: <Task finished name='Task-19' coro=<shutdown_and_exit() done, defined at /home/thalles/Documentos/ProjetosGit/Estudo_DeepSeek_Ollma/API/api_deepseek.py:218> exception=SystemExit(1)>
[18:11:45] ‚úÖ Connected to database sqlite:////home/thalles/Documentos/ProjetosGit/Estudo_DeepSeek_Ollma/API/db/api_logs.db
[18:12:06] ‚úÖ Servidor iniciado com sucesso na porta 5000
[18:12:06] ‚úÖ Running on http://127.0.0.1:5000 (CTRL + C to quit)
[18:12:12] ‚õî Erro inesperado: 404 Not Found: The requested URL was not found on the server. If you entered the URL manually please check your spelling and try again.
[18:12:12] ‚õî Erro inesperado: 404 Not Found: The requested URL was not found on the server. If you entered the URL manually please check your spelling and try again.
[18:12:12] ‚õî Task exception was never retrieved
future: <Task finished name='Task-19' coro=<shutdown_and_exit() done, defined at /home/thalles/Documentos/ProjetosGit/Estudo_DeepSeek_Ollma/API/api_deepseek.py:218> exception=SystemExit(1)>
2025-02-09 18:13:33,446 [INFO] [31m[1mWARNING: This is a development server. Do not use it in a production deployment. Use a production WSGI server instead.[0m
 * Running on all addresses (0.0.0.0)
 * Running on http://127.0.0.1:5000
 * Running on http://192.168.3.100:5000
2025-02-09 18:13:33,446 [INFO] [33mPress CTRL+C to quit[0m
2025-02-09 18:13:38,002 [INFO] 127.0.0.1 - - [09/Feb/2025 18:13:38] "[33mGET / HTTP/1.1[0m" 404 -
2025-02-09 18:13:38,048 [INFO] 127.0.0.1 - - [09/Feb/2025 18:13:38] "[33mGET /favicon.ico HTTP/1.1[0m" 404 -
2025-02-09 18:13:46,550 [INFO] 127.0.0.1 - - [09/Feb/2025 18:13:46] "[33mGET / HTTP/1.1[0m" 404 -
2025-02-09 18:13:46,636 [INFO] 127.0.0.1 - - [09/Feb/2025 18:13:46] "[33mGET /favicon.ico HTTP/1.1[0m" 404 -
2025-02-09 18:19:36,315 [INFO] [+] Iniciando servidor na porta 5000
2025-02-09 18:19:36,321 [INFO] Connected to database sqlite:////home/thalles/Documentos/ProjetosGit/Estudo_DeepSeek_Ollma/API/db/api_logs.db
2025-02-09 18:19:36,322 [INFO] Running on http://0.0.0.0:5000 (CTRL + C to quit)
2025-02-09 18:20:18,701 [INFO] [+] Iniciando servidor na porta 5000
2025-02-09 18:20:18,706 [INFO] Connected to database sqlite:////home/thalles/Documentos/ProjetosGit/Estudo_DeepSeek_Ollma/API/db/api_logs.db
2025-02-09 18:20:18,708 [INFO] Running on http://0.0.0.0:5000 (CTRL + C to quit)
2025-02-09 18:20:42,231 [INFO] Disconnected from database sqlite:////home/thalles/Documentos/ProjetosGit/Estudo_DeepSeek_Ollma/API/db/api_logs.db
2025-02-09 18:20:44,857 [INFO] [+] Iniciando servidor na porta 5000
2025-02-09 18:20:44,863 [INFO] Connected to database sqlite:////home/thalles/Documentos/ProjetosGit/Estudo_DeepSeek_Ollma/API/db/api_logs.db
2025-02-09 18:20:44,864 [INFO] Running on http://0.0.0.0:5000 (CTRL + C to quit)
2025-02-09 18:23:08,504 [INFO] [+] Iniciando servidor na porta 5000
2025-02-09 18:23:08,511 [INFO] Connected to database sqlite:////home/thalles/Documentos/ProjetosGit/Estudo_DeepSeek_Ollma/API/db/api_logs.db
2025-02-09 18:23:08,513 [INFO] Connected to database sqlite:////home/thalles/Documentos/ProjetosGit/Estudo_DeepSeek_Ollma/API/db/api_logs.db
2025-02-09 18:23:08,514 [INFO] Running on http://0.0.0.0:5000 (CTRL + C to quit)
2025-02-09 18:23:12,264 [INFO] Disconnected from database sqlite:////home/thalles/Documentos/ProjetosGit/Estudo_DeepSeek_Ollma/API/db/api_logs.db
2025-02-09 18:23:15,293 [INFO] [+] Iniciando servidor na porta 5000
2025-02-09 18:23:15,299 [INFO] Connected to database sqlite:////home/thalles/Documentos/ProjetosGit/Estudo_DeepSeek_Ollma/API/db/api_logs.db
2025-02-09 18:23:15,301 [INFO] Connected to database sqlite:////home/thalles/Documentos/ProjetosGit/Estudo_DeepSeek_Ollma/API/db/api_logs.db
2025-02-09 18:23:15,302 [INFO] Running on http://0.0.0.0:5000 (CTRL + C to quit)
2025-02-09 18:23:50,689 [INFO] [+] Iniciando servidor na porta 5000
2025-02-09 18:23:50,695 [INFO] Connected to database sqlite:////home/thalles/Documentos/ProjetosGit/Estudo_DeepSeek_Ollma/API/db/api_logs.db
2025-02-09 18:23:50,697 [INFO] Running on http://0.0.0.0:5000 (CTRL + C to quit)
2025-02-09 18:23:53,814 [INFO] Disconnected from database sqlite:////home/thalles/Documentos/ProjetosGit/Estudo_DeepSeek_Ollma/API/db/api_logs.db
2025-02-09 18:23:55,807 [INFO] [+] Iniciando servidor na porta 5000
2025-02-09 18:23:55,813 [INFO] Connected to database sqlite:////home/thalles/Documentos/ProjetosGit/Estudo_DeepSeek_Ollma/API/db/api_logs.db
2025-02-09 18:23:55,815 [INFO] Running on http://0.0.0.0:5000 (CTRL + C to quit)
[18:24:36] [INFO] üöÄ [+] Iniciando servidor na porta 5000
[18:24:36] [INFO] Connected to database sqlite:////home/thalles/Documentos/ProjetosGit/Estudo_DeepSeek_Ollma/API/db/api_logs.db
[18:24:36] [INFO] üóÑÔ∏è  [INFO] Connected to database sqlite:////home/thalles/Documentos/ProjetosGit/Estudo_DeepSeek_Ollma/API/db/api_logs.db
[18:24:36] [INFO] Running on http://0.0.0.0:5000 (CTRL + C to quit)
[18:24:37] [INFO] üöÄ [+] Iniciando servidor na porta 5000
[18:24:37] [INFO] Connected to database sqlite:////home/thalles/Documentos/ProjetosGit/Estudo_DeepSeek_Ollma/API/db/api_logs.db
[18:24:37] [INFO] üóÑÔ∏è  [INFO] Connected to database sqlite:////home/thalles/Documentos/ProjetosGit/Estudo_DeepSeek_Ollma/API/db/api_logs.db
[18:24:37] [INFO] Running on http://0.0.0.0:5000 (CTRL + C to quit)
[18:24:38] [INFO] Disconnected from database sqlite:////home/thalles/Documentos/ProjetosGit/Estudo_DeepSeek_Ollma/API/db/api_logs.db
[18:24:40] [INFO] üöÄ [+] Iniciando servidor na porta 5000
[18:24:40] [INFO] Connected to database sqlite:////home/thalles/Documentos/ProjetosGit/Estudo_DeepSeek_Ollma/API/db/api_logs.db
[18:24:40] [INFO] üóÑÔ∏è  [INFO] Connected to database sqlite:////home/thalles/Documentos/ProjetosGit/Estudo_DeepSeek_Ollma/API/db/api_logs.db
[18:24:40] [INFO] Running on http://0.0.0.0:5000 (CTRL + C to quit)
[18:25:10] [ERROR] Exception on request POST /analyze
Traceback (most recent call last):
  File "/usr/local/lib/python3.11/dist-packages/quart/app.py", line 1464, in handle_request
    return await self.full_dispatch_request(request_context)
           ^^^^^^^^^^^^^^^^^^^^^^^^^^^^^^^^^^^^^^^^^^^^^^^^^
  File "/usr/local/lib/python3.11/dist-packages/quart/app.py", line 1502, in full_dispatch_request
    result = await self.handle_user_exception(error)
             ^^^^^^^^^^^^^^^^^^^^^^^^^^^^^^^^^^^^^^^
  File "/usr/local/lib/python3.11/dist-packages/quart/app.py", line 1059, in handle_user_exception
    raise error
  File "/usr/local/lib/python3.11/dist-packages/quart/app.py", line 1498, in full_dispatch_request
    result = await self.preprocess_request(request_context)
             ^^^^^^^^^^^^^^^^^^^^^^^^^^^^^^^^^^^^^^^^^^^^^^
  File "/usr/local/lib/python3.11/dist-packages/quart/app.py", line 1545, in preprocess_request
    result = await self.ensure_async(function)()
             ^^^^^^^^^^^^^^^^^^^^^^^^^^^^^^^^^^^
  File "/usr/local/lib/python3.11/dist-packages/quart_rate_limiter/__init__.py", line 281, in _before_request
    await self._raise_on_rejection(endpoint, rate_limits)
  File "/usr/local/lib/python3.11/dist-packages/quart_rate_limiter/__init__.py", line 287, in _raise_on_rejection
    key = await self._create_key(endpoint, rate_limit)
          ^^^^^^^^^^^^^^^^^^^^^^^^^^^^^^^^^^^^^^^^^^^^
  File "/usr/local/lib/python3.11/dist-packages/quart_rate_limiter/__init__.py", line 335, in _create_key
    return f"{app_name}-{endpoint}-{rate_limit.key}-{key}"
                                    ^^^^^^^^^^^^^^
  File "/usr/local/lib/python3.11/dist-packages/quart_rate_limiter/__init__.py", line 50, in key
    return f"{self.count}-{self.period.total_seconds()}"
                           ^^^^^^^^^^^^^^^^^^^^^^^^^
AttributeError: 'int' object has no attribute 'total_seconds'
[18:25:10] [ERROR] Request finalizing errored
Traceback (most recent call last):
  File "/usr/local/lib/python3.11/dist-packages/quart/app.py", line 1464, in handle_request
    return await self.full_dispatch_request(request_context)
           ^^^^^^^^^^^^^^^^^^^^^^^^^^^^^^^^^^^^^^^^^^^^^^^^^
  File "/usr/local/lib/python3.11/dist-packages/quart/app.py", line 1502, in full_dispatch_request
    result = await self.handle_user_exception(error)
             ^^^^^^^^^^^^^^^^^^^^^^^^^^^^^^^^^^^^^^^
  File "/usr/local/lib/python3.11/dist-packages/quart/app.py", line 1059, in handle_user_exception
    raise error
  File "/usr/local/lib/python3.11/dist-packages/quart/app.py", line 1498, in full_dispatch_request
    result = await self.preprocess_request(request_context)
             ^^^^^^^^^^^^^^^^^^^^^^^^^^^^^^^^^^^^^^^^^^^^^^
  File "/usr/local/lib/python3.11/dist-packages/quart/app.py", line 1545, in preprocess_request
    result = await self.ensure_async(function)()
             ^^^^^^^^^^^^^^^^^^^^^^^^^^^^^^^^^^^
  File "/usr/local/lib/python3.11/dist-packages/quart_rate_limiter/__init__.py", line 281, in _before_request
    await self._raise_on_rejection(endpoint, rate_limits)
  File "/usr/local/lib/python3.11/dist-packages/quart_rate_limiter/__init__.py", line 287, in _raise_on_rejection
    key = await self._create_key(endpoint, rate_limit)
          ^^^^^^^^^^^^^^^^^^^^^^^^^^^^^^^^^^^^^^^^^^^^
  File "/usr/local/lib/python3.11/dist-packages/quart_rate_limiter/__init__.py", line 335, in _create_key
    return f"{app_name}-{endpoint}-{rate_limit.key}-{key}"
                                    ^^^^^^^^^^^^^^
  File "/usr/local/lib/python3.11/dist-packages/quart_rate_limiter/__init__.py", line 50, in key
    return f"{self.count}-{self.period.total_seconds()}"
                           ^^^^^^^^^^^^^^^^^^^^^^^^^
AttributeError: 'int' object has no attribute 'total_seconds'

During handling of the above exception, another exception occurred:

Traceback (most recent call last):
  File "/usr/local/lib/python3.11/dist-packages/quart/app.py", line 1630, in finalize_request
    response = await self.process_response(response, request_context)
               ^^^^^^^^^^^^^^^^^^^^^^^^^^^^^^^^^^^^^^^^^^^^^^^^^^^^^^
  File "/usr/local/lib/python3.11/dist-packages/quart/app.py", line 1691, in process_response
    response = await self.ensure_async(function)(response)
               ^^^^^^^^^^^^^^^^^^^^^^^^^^^^^^^^^^^^^^^^^^^
  File "/usr/local/lib/python3.11/dist-packages/quart_rate_limiter/__init__.py", line 316, in _after_request
    min_limit = min(rate_limits, key=lambda rate_limit: rate_limit.period.total_seconds())
                ^^^^^^^^^^^^^^^^^^^^^^^^^^^^^^^^^^^^^^^^^^^^^^^^^^^^^^^^^^^^^^^^^^^^^^^^^^
  File "/usr/local/lib/python3.11/dist-packages/quart_rate_limiter/__init__.py", line 316, in <lambda>
    min_limit = min(rate_limits, key=lambda rate_limit: rate_limit.period.total_seconds())
                                                        ^^^^^^^^^^^^^^^^^^^^^^^^^^^^^^^
AttributeError: 'int' object has no attribute 'total_seconds'
[18:25:38] [INFO] üöÄ [+] Iniciando servidor na porta 5000
[18:25:38] [INFO] Connected to database sqlite:////home/thalles/Documentos/ProjetosGit/Estudo_DeepSeek_Ollma/API/db/api_logs.db
[18:25:38] [INFO] üóÑÔ∏è  [INFO] Connected to database sqlite:////home/thalles/Documentos/ProjetosGit/Estudo_DeepSeek_Ollma/API/db/api_logs.db
[18:25:38] [INFO] Running on http://0.0.0.0:5000 (CTRL + C to quit)
[18:25:40] [INFO] Disconnected from database sqlite:////home/thalles/Documentos/ProjetosGit/Estudo_DeepSeek_Ollma/API/db/api_logs.db
[18:25:43] [INFO] üöÄ [+] Iniciando servidor na porta 5000
[18:25:43] [INFO] Connected to database sqlite:////home/thalles/Documentos/ProjetosGit/Estudo_DeepSeek_Ollma/API/db/api_logs.db
[18:25:43] [INFO] üóÑÔ∏è  [INFO] Connected to database sqlite:////home/thalles/Documentos/ProjetosGit/Estudo_DeepSeek_Ollma/API/db/api_logs.db
[18:25:43] [INFO] Running on http://0.0.0.0:5000 (CTRL + C to quit)
[18:25:46] [ERROR] Exception on request POST /analyze
Traceback (most recent call last):
  File "/usr/local/lib/python3.11/dist-packages/quart/app.py", line 1464, in handle_request
    return await self.full_dispatch_request(request_context)
           ^^^^^^^^^^^^^^^^^^^^^^^^^^^^^^^^^^^^^^^^^^^^^^^^^
  File "/usr/local/lib/python3.11/dist-packages/quart/app.py", line 1502, in full_dispatch_request
    result = await self.handle_user_exception(error)
             ^^^^^^^^^^^^^^^^^^^^^^^^^^^^^^^^^^^^^^^
  File "/usr/local/lib/python3.11/dist-packages/quart/app.py", line 1059, in handle_user_exception
    raise error
  File "/usr/local/lib/python3.11/dist-packages/quart/app.py", line 1498, in full_dispatch_request
    result = await self.preprocess_request(request_context)
             ^^^^^^^^^^^^^^^^^^^^^^^^^^^^^^^^^^^^^^^^^^^^^^
  File "/usr/local/lib/python3.11/dist-packages/quart/app.py", line 1545, in preprocess_request
    result = await self.ensure_async(function)()
             ^^^^^^^^^^^^^^^^^^^^^^^^^^^^^^^^^^^
  File "/usr/local/lib/python3.11/dist-packages/quart_rate_limiter/__init__.py", line 281, in _before_request
    await self._raise_on_rejection(endpoint, rate_limits)
  File "/usr/local/lib/python3.11/dist-packages/quart_rate_limiter/__init__.py", line 287, in _raise_on_rejection
    key = await self._create_key(endpoint, rate_limit)
          ^^^^^^^^^^^^^^^^^^^^^^^^^^^^^^^^^^^^^^^^^^^^
  File "/usr/local/lib/python3.11/dist-packages/quart_rate_limiter/__init__.py", line 335, in _create_key
    return f"{app_name}-{endpoint}-{rate_limit.key}-{key}"
                                    ^^^^^^^^^^^^^^
  File "/usr/local/lib/python3.11/dist-packages/quart_rate_limiter/__init__.py", line 50, in key
    return f"{self.count}-{self.period.total_seconds()}"
                           ^^^^^^^^^^^^^^^^^^^^^^^^^
AttributeError: 'int' object has no attribute 'total_seconds'
[18:25:46] [ERROR] Request finalizing errored
Traceback (most recent call last):
  File "/usr/local/lib/python3.11/dist-packages/quart/app.py", line 1464, in handle_request
    return await self.full_dispatch_request(request_context)
           ^^^^^^^^^^^^^^^^^^^^^^^^^^^^^^^^^^^^^^^^^^^^^^^^^
  File "/usr/local/lib/python3.11/dist-packages/quart/app.py", line 1502, in full_dispatch_request
    result = await self.handle_user_exception(error)
             ^^^^^^^^^^^^^^^^^^^^^^^^^^^^^^^^^^^^^^^
  File "/usr/local/lib/python3.11/dist-packages/quart/app.py", line 1059, in handle_user_exception
    raise error
  File "/usr/local/lib/python3.11/dist-packages/quart/app.py", line 1498, in full_dispatch_request
    result = await self.preprocess_request(request_context)
             ^^^^^^^^^^^^^^^^^^^^^^^^^^^^^^^^^^^^^^^^^^^^^^
  File "/usr/local/lib/python3.11/dist-packages/quart/app.py", line 1545, in preprocess_request
    result = await self.ensure_async(function)()
             ^^^^^^^^^^^^^^^^^^^^^^^^^^^^^^^^^^^
  File "/usr/local/lib/python3.11/dist-packages/quart_rate_limiter/__init__.py", line 281, in _before_request
    await self._raise_on_rejection(endpoint, rate_limits)
  File "/usr/local/lib/python3.11/dist-packages/quart_rate_limiter/__init__.py", line 287, in _raise_on_rejection
    key = await self._create_key(endpoint, rate_limit)
          ^^^^^^^^^^^^^^^^^^^^^^^^^^^^^^^^^^^^^^^^^^^^
  File "/usr/local/lib/python3.11/dist-packages/quart_rate_limiter/__init__.py", line 335, in _create_key
    return f"{app_name}-{endpoint}-{rate_limit.key}-{key}"
                                    ^^^^^^^^^^^^^^
  File "/usr/local/lib/python3.11/dist-packages/quart_rate_limiter/__init__.py", line 50, in key
    return f"{self.count}-{self.period.total_seconds()}"
                           ^^^^^^^^^^^^^^^^^^^^^^^^^
AttributeError: 'int' object has no attribute 'total_seconds'

During handling of the above exception, another exception occurred:

Traceback (most recent call last):
  File "/usr/local/lib/python3.11/dist-packages/quart/app.py", line 1630, in finalize_request
    response = await self.process_response(response, request_context)
               ^^^^^^^^^^^^^^^^^^^^^^^^^^^^^^^^^^^^^^^^^^^^^^^^^^^^^^
  File "/usr/local/lib/python3.11/dist-packages/quart/app.py", line 1691, in process_response
    response = await self.ensure_async(function)(response)
               ^^^^^^^^^^^^^^^^^^^^^^^^^^^^^^^^^^^^^^^^^^^
  File "/usr/local/lib/python3.11/dist-packages/quart_rate_limiter/__init__.py", line 316, in _after_request
    min_limit = min(rate_limits, key=lambda rate_limit: rate_limit.period.total_seconds())
                ^^^^^^^^^^^^^^^^^^^^^^^^^^^^^^^^^^^^^^^^^^^^^^^^^^^^^^^^^^^^^^^^^^^^^^^^^^
  File "/usr/local/lib/python3.11/dist-packages/quart_rate_limiter/__init__.py", line 316, in <lambda>
    min_limit = min(rate_limits, key=lambda rate_limit: rate_limit.period.total_seconds())
                                                        ^^^^^^^^^^^^^^^^^^^^^^^^^^^^^^^
AttributeError: 'int' object has no attribute 'total_seconds'
2025-02-09 18:25:54,184 [INFO] [+] Iniciando servidor na porta 5000
2025-02-09 18:25:54,190 [INFO] Connected to database sqlite:////home/thalles/Documentos/ProjetosGit/Estudo_DeepSeek_Ollma/API/db/api_logs.db
2025-02-09 18:25:54,191 [INFO] Running on http://0.0.0.0:5000 (CTRL + C to quit)
2025-02-09 18:26:08,635 [INFO] [31m[1mWARNING: This is a development server. Do not use it in a production deployment. Use a production WSGI server instead.[0m
 * Running on all addresses (0.0.0.0)
 * Running on http://127.0.0.1:5000
 * Running on http://192.168.3.100:5000
2025-02-09 18:26:08,635 [INFO] [33mPress CTRL+C to quit[0m
2025-02-09 18:28:32,385 [INFO] [+] Iniciando servidor na porta 5000
2025-02-09 18:28:32,391 [INFO] Connected to database sqlite:////home/thalles/Documentos/ProjetosGit/Estudo_DeepSeek_Ollma/API/db/api_logs.db
2025-02-09 18:28:32,392 [INFO] Running on http://0.0.0.0:5000 (CTRL + C to quit)
2025-02-09 18:28:38,563 [ERROR] Exception on request POST /analyze
Traceback (most recent call last):
  File "/usr/local/lib/python3.11/dist-packages/quart/app.py", line 1464, in handle_request
    return await self.full_dispatch_request(request_context)
           ^^^^^^^^^^^^^^^^^^^^^^^^^^^^^^^^^^^^^^^^^^^^^^^^^
  File "/usr/local/lib/python3.11/dist-packages/quart/app.py", line 1502, in full_dispatch_request
    result = await self.handle_user_exception(error)
             ^^^^^^^^^^^^^^^^^^^^^^^^^^^^^^^^^^^^^^^
  File "/usr/local/lib/python3.11/dist-packages/quart/app.py", line 1059, in handle_user_exception
    raise error
  File "/usr/local/lib/python3.11/dist-packages/quart/app.py", line 1498, in full_dispatch_request
    result = await self.preprocess_request(request_context)
             ^^^^^^^^^^^^^^^^^^^^^^^^^^^^^^^^^^^^^^^^^^^^^^
  File "/usr/local/lib/python3.11/dist-packages/quart/app.py", line 1545, in preprocess_request
    result = await self.ensure_async(function)()
             ^^^^^^^^^^^^^^^^^^^^^^^^^^^^^^^^^^^
  File "/usr/local/lib/python3.11/dist-packages/quart_rate_limiter/__init__.py", line 281, in _before_request
    await self._raise_on_rejection(endpoint, rate_limits)
  File "/usr/local/lib/python3.11/dist-packages/quart_rate_limiter/__init__.py", line 287, in _raise_on_rejection
    key = await self._create_key(endpoint, rate_limit)
          ^^^^^^^^^^^^^^^^^^^^^^^^^^^^^^^^^^^^^^^^^^^^
  File "/usr/local/lib/python3.11/dist-packages/quart_rate_limiter/__init__.py", line 335, in _create_key
    return f"{app_name}-{endpoint}-{rate_limit.key}-{key}"
                                    ^^^^^^^^^^^^^^
  File "/usr/local/lib/python3.11/dist-packages/quart_rate_limiter/__init__.py", line 50, in key
    return f"{self.count}-{self.period.total_seconds()}"
                           ^^^^^^^^^^^^^^^^^^^^^^^^^
AttributeError: 'int' object has no attribute 'total_seconds'
2025-02-09 18:28:38,564 [ERROR] Request finalizing errored
Traceback (most recent call last):
  File "/usr/local/lib/python3.11/dist-packages/quart/app.py", line 1464, in handle_request
    return await self.full_dispatch_request(request_context)
           ^^^^^^^^^^^^^^^^^^^^^^^^^^^^^^^^^^^^^^^^^^^^^^^^^
  File "/usr/local/lib/python3.11/dist-packages/quart/app.py", line 1502, in full_dispatch_request
    result = await self.handle_user_exception(error)
             ^^^^^^^^^^^^^^^^^^^^^^^^^^^^^^^^^^^^^^^
  File "/usr/local/lib/python3.11/dist-packages/quart/app.py", line 1059, in handle_user_exception
    raise error
  File "/usr/local/lib/python3.11/dist-packages/quart/app.py", line 1498, in full_dispatch_request
    result = await self.preprocess_request(request_context)
             ^^^^^^^^^^^^^^^^^^^^^^^^^^^^^^^^^^^^^^^^^^^^^^
  File "/usr/local/lib/python3.11/dist-packages/quart/app.py", line 1545, in preprocess_request
    result = await self.ensure_async(function)()
             ^^^^^^^^^^^^^^^^^^^^^^^^^^^^^^^^^^^
  File "/usr/local/lib/python3.11/dist-packages/quart_rate_limiter/__init__.py", line 281, in _before_request
    await self._raise_on_rejection(endpoint, rate_limits)
  File "/usr/local/lib/python3.11/dist-packages/quart_rate_limiter/__init__.py", line 287, in _raise_on_rejection
    key = await self._create_key(endpoint, rate_limit)
          ^^^^^^^^^^^^^^^^^^^^^^^^^^^^^^^^^^^^^^^^^^^^
  File "/usr/local/lib/python3.11/dist-packages/quart_rate_limiter/__init__.py", line 335, in _create_key
    return f"{app_name}-{endpoint}-{rate_limit.key}-{key}"
                                    ^^^^^^^^^^^^^^
  File "/usr/local/lib/python3.11/dist-packages/quart_rate_limiter/__init__.py", line 50, in key
    return f"{self.count}-{self.period.total_seconds()}"
                           ^^^^^^^^^^^^^^^^^^^^^^^^^
AttributeError: 'int' object has no attribute 'total_seconds'

During handling of the above exception, another exception occurred:

Traceback (most recent call last):
  File "/usr/local/lib/python3.11/dist-packages/quart/app.py", line 1630, in finalize_request
    response = await self.process_response(response, request_context)
               ^^^^^^^^^^^^^^^^^^^^^^^^^^^^^^^^^^^^^^^^^^^^^^^^^^^^^^
  File "/usr/local/lib/python3.11/dist-packages/quart/app.py", line 1691, in process_response
    response = await self.ensure_async(function)(response)
               ^^^^^^^^^^^^^^^^^^^^^^^^^^^^^^^^^^^^^^^^^^^
  File "/usr/local/lib/python3.11/dist-packages/quart_rate_limiter/__init__.py", line 316, in _after_request
    min_limit = min(rate_limits, key=lambda rate_limit: rate_limit.period.total_seconds())
                ^^^^^^^^^^^^^^^^^^^^^^^^^^^^^^^^^^^^^^^^^^^^^^^^^^^^^^^^^^^^^^^^^^^^^^^^^^
  File "/usr/local/lib/python3.11/dist-packages/quart_rate_limiter/__init__.py", line 316, in <lambda>
    min_limit = min(rate_limits, key=lambda rate_limit: rate_limit.period.total_seconds())
                                                        ^^^^^^^^^^^^^^^^^^^^^^^^^^^^^^^
AttributeError: 'int' object has no attribute 'total_seconds'
2025-02-09 18:28:45,288 [INFO] Disconnected from database sqlite:////home/thalles/Documentos/ProjetosGit/Estudo_DeepSeek_Ollma/API/db/api_logs.db
2025-02-09 18:28:59,700 [INFO] [31m[1mWARNING: This is a development server. Do not use it in a production deployment. Use a production WSGI server instead.[0m
 * Running on all addresses (0.0.0.0)
 * Running on http://127.0.0.1:5000
 * Running on http://192.168.3.100:5000
2025-02-09 18:28:59,700 [INFO] [33mPress CTRL+C to quit[0m
2025-02-09 18:30:13,137 [INFO] 127.0.0.1 - - [09/Feb/2025 18:30:13] "POST /analyze HTTP/1.1" 200 -
2025-02-09 18:34:14,478 [INFO] Connected to database sqlite:////home/thalles/Documentos/ProjetosGit/Estudo_DeepSeek_Ollma/API/db/api_logs.db
2025-02-09 18:34:14,511 [ERROR] Falha no teste do Ollama: All connection attempts failed
2025-02-09 18:34:14,529 [ERROR] _GatheringFuture exception was never retrieved
future: <_GatheringFuture finished exception=CancelledError()>
Traceback (most recent call last):
  File "/home/thalles/Documentos/ProjetosGit/Estudo_DeepSeek_Ollma/API/api_deepseek.py", line 266, in <module>
    app.run(host="0.0.0.0", port=API_PORT)
  File "/usr/local/lib/python3.11/dist-packages/quart/app.py", line 878, in run
    loop.run_until_complete(asyncio.gather(*tasks))
  File "/usr/lib/python3.11/asyncio/base_events.py", line 640, in run_until_complete
    self.run_forever()
  File "/usr/lib/python3.11/asyncio/base_events.py", line 607, in run_forever
    self._run_once()
  File "/usr/lib/python3.11/asyncio/base_events.py", line 1922, in _run_once
    handle._run()
  File "/usr/lib/python3.11/asyncio/events.py", line 80, in _run
    self._context.run(self._callback, *self._args)
  File "/usr/local/lib/python3.11/dist-packages/hypercorn/asyncio/lifespan.py", line 55, in handle_lifespan
    await self.app(
  File "/usr/local/lib/python3.11/dist-packages/hypercorn/app_wrappers.py", line 34, in __call__
    await self.app(scope, receive, send)
  File "/usr/local/lib/python3.11/dist-packages/quart/app.py", line 1735, in __call__
    await self.asgi_app(scope, receive, send)
  File "/usr/local/lib/python3.11/dist-packages/quart/app.py", line 1761, in asgi_app
    await asgi_handler(receive, send)
  File "/usr/local/lib/python3.11/dist-packages/quart/asgi.py", line 365, in __call__
    await self.app.startup()
  File "/usr/local/lib/python3.11/dist-packages/quart/app.py", line 1768, in startup
    await self.ensure_async(func)()
  File "/home/thalles/Documentos/ProjetosGit/Estudo_DeepSeek_Ollma/API/api_deepseek.py", line 255, in startup
    sys.exit(1)
SystemExit: 1

During handling of the above exception, another exception occurred:

Traceback (most recent call last):
  File "/usr/lib/python3.11/asyncio/tasks.py", line 466, in wait_for
    await waiter
asyncio.exceptions.CancelledError

During handling of the above exception, another exception occurred:

Traceback (most recent call last):
  File "/usr/local/lib/python3.11/dist-packages/hypercorn/asyncio/__init__.py", line 44, in serve
    await worker_serve(
  File "/usr/local/lib/python3.11/dist-packages/hypercorn/asyncio/run.py", line 84, in worker_serve
    await lifespan.wait_for_startup()
  File "/usr/local/lib/python3.11/dist-packages/hypercorn/asyncio/lifespan.py", line 94, in wait_for_startup
    await asyncio.wait_for(self.startup.wait(), timeout=self.config.startup_timeout)
  File "/usr/lib/python3.11/asyncio/tasks.py", line 469, in wait_for
    return fut.result()
           ^^^^^^^^^^^^
  File "/usr/lib/python3.11/asyncio/locks.py", line 213, in wait
    await fut
asyncio.exceptions.CancelledError
2025-02-09 18:34:14,532 [ERROR] Task exception was never retrieved
future: <Task finished name='Task-3' coro=<Lifespan.handle_lifespan() done, defined at /usr/local/lib/python3.11/dist-packages/hypercorn/asyncio/lifespan.py:42> exception=SystemExit(1)>
Traceback (most recent call last):
  File "/home/thalles/Documentos/ProjetosGit/Estudo_DeepSeek_Ollma/API/api_deepseek.py", line 266, in <module>
    app.run(host="0.0.0.0", port=API_PORT)
  File "/usr/local/lib/python3.11/dist-packages/quart/app.py", line 878, in run
    loop.run_until_complete(asyncio.gather(*tasks))
  File "/usr/lib/python3.11/asyncio/base_events.py", line 640, in run_until_complete
    self.run_forever()
  File "/usr/lib/python3.11/asyncio/base_events.py", line 607, in run_forever
    self._run_once()
  File "/usr/lib/python3.11/asyncio/base_events.py", line 1922, in _run_once
    handle._run()
  File "/usr/lib/python3.11/asyncio/events.py", line 80, in _run
    self._context.run(self._callback, *self._args)
  File "/usr/local/lib/python3.11/dist-packages/hypercorn/asyncio/lifespan.py", line 55, in handle_lifespan
    await self.app(
  File "/usr/local/lib/python3.11/dist-packages/hypercorn/app_wrappers.py", line 34, in __call__
    await self.app(scope, receive, send)
  File "/usr/local/lib/python3.11/dist-packages/quart/app.py", line 1735, in __call__
    await self.asgi_app(scope, receive, send)
  File "/usr/local/lib/python3.11/dist-packages/quart/app.py", line 1761, in asgi_app
    await asgi_handler(receive, send)
  File "/usr/local/lib/python3.11/dist-packages/quart/asgi.py", line 365, in __call__
    await self.app.startup()
  File "/usr/local/lib/python3.11/dist-packages/quart/app.py", line 1768, in startup
    await self.ensure_async(func)()
  File "/home/thalles/Documentos/ProjetosGit/Estudo_DeepSeek_Ollma/API/api_deepseek.py", line 255, in startup
    sys.exit(1)
SystemExit: 1
2025-02-09 18:34:59,349 [INFO] [31m[1mWARNING: This is a development server. Do not use it in a production deployment. Use a production WSGI server instead.[0m
 * Running on all addresses (0.0.0.0)
 * Running on http://127.0.0.1:5000
 * Running on http://192.168.3.100:5000
2025-02-09 18:34:59,349 [INFO] [33mPress CTRL+C to quit[0m
2025-02-09 18:40:01,424 [INFO] [31m[1mWARNING: This is a development server. Do not use it in a production deployment. Use a production WSGI server instead.[0m
 * Running on all addresses (0.0.0.0)
 * Running on http://127.0.0.1:5000
 * Running on http://192.168.3.100:5000
2025-02-09 18:40:01,424 [INFO] [33mPress CTRL+C to quit[0m
2025-02-09 18:41:50,410 [INFO] [31m[1mWARNING: This is a development server. Do not use it in a production deployment. Use a production WSGI server instead.[0m
 * Running on all addresses (0.0.0.0)
 * Running on http://127.0.0.1:5000
 * Running on http://192.168.3.100:5000
2025-02-09 18:41:50,410 [INFO] [33mPress CTRL+C to quit[0m
